[2023-11-03T01:37:42.958-0300] {taskinstance.py:1159} INFO - Dependencies all met for dep_context=non-requeueable deps ti=<TaskInstance: DesafioAirflow.extract_order_csv manual__2023-11-03T04:37:39.594122+00:00 [queued]>
[2023-11-03T01:37:42.961-0300] {taskinstance.py:1159} INFO - Dependencies all met for dep_context=requeueable deps ti=<TaskInstance: DesafioAirflow.extract_order_csv manual__2023-11-03T04:37:39.594122+00:00 [queued]>
[2023-11-03T01:37:42.961-0300] {taskinstance.py:1361} INFO - Starting attempt 1 of 2
[2023-11-03T01:37:42.971-0300] {taskinstance.py:1382} INFO - Executing <Task(PythonOperator): extract_order_csv> on 2023-11-03 04:37:39.594122+00:00
[2023-11-03T01:37:42.974-0300] {standard_task_runner.py:57} INFO - Started process 19432 to run task
[2023-11-03T01:37:42.975-0300] {standard_task_runner.py:84} INFO - Running: ['airflow', 'tasks', 'run', 'DesafioAirflow', 'extract_order_csv', 'manual__2023-11-03T04:37:39.594122+00:00', '--job-id', '4', '--raw', '--subdir', 'DAGS_FOLDER/example_desafio.py', '--cfg-path', '/tmp/tmpwnlnvpb9']
[2023-11-03T01:37:42.975-0300] {standard_task_runner.py:85} INFO - Job 4: Subtask extract_order_csv
[2023-11-03T01:37:42.993-0300] {task_command.py:416} INFO - Running <TaskInstance: DesafioAirflow.extract_order_csv manual__2023-11-03T04:37:39.594122+00:00 [running]> on host Felipe.
[2023-11-03T01:37:43.025-0300] {taskinstance.py:1662} INFO - Exporting env vars: AIRFLOW_CTX_DAG_EMAIL='airflow@example.com' AIRFLOW_CTX_DAG_OWNER='airflow' AIRFLOW_CTX_DAG_ID='DesafioAirflow' AIRFLOW_CTX_TASK_ID='extract_order_csv' AIRFLOW_CTX_EXECUTION_DATE='2023-11-03T04:37:39.594122+00:00' AIRFLOW_CTX_TRY_NUMBER='1' AIRFLOW_CTX_DAG_RUN_ID='manual__2023-11-03T04:37:39.594122+00:00'
[2023-11-03T01:37:43.026-0300] {taskinstance.py:1937} ERROR - Task failed with exception
Traceback (most recent call last):
  File "/home/felipe/venv/lib/python3.9/site-packages/airflow/operators/python.py", line 192, in execute
    return_value = self.execute_callable()
  File "/home/felipe/venv/lib/python3.9/site-packages/airflow/operators/python.py", line 209, in execute_callable
    return self.python_callable(*self.op_args, **self.op_kwargs)
  File "/home/felipe/airflow/dags/example_desafio.py", line 44, in extract_order
    con = sqlite3.connect("home/felipe/airflow_tooltorial/data/Northwind_small.sqlite")
sqlite3.OperationalError: unable to open database file
[2023-11-03T01:37:43.028-0300] {taskinstance.py:1400} INFO - Marking task as UP_FOR_RETRY. dag_id=DesafioAirflow, task_id=extract_order_csv, execution_date=20231103T043739, start_date=20231103T043742, end_date=20231103T043743
[2023-11-03T01:37:43.037-0300] {logging_mixin.py:151} WARNING - /home/felipe/venv/lib/python3.9/site-packages/airflow/utils/email.py:154 RemovedInAirflow3Warning: Fetching SMTP credentials from configuration variables will be deprecated in a future release. Please set credentials using a connection instead.
[2023-11-03T01:37:43.037-0300] {configuration.py:1068} WARNING - section/key [smtp/smtp_user] not found in config
[2023-11-03T01:37:43.037-0300] {email.py:270} INFO - Email alerting: attempt 1
[2023-11-03T01:37:43.038-0300] {configuration.py:1068} WARNING - section/key [smtp/smtp_user] not found in config
[2023-11-03T01:37:43.038-0300] {email.py:270} INFO - Email alerting: attempt 1
[2023-11-03T01:37:43.038-0300] {taskinstance.py:2007} ERROR - Failed to send email to: ['airflow@example.com']
Traceback (most recent call last):
  File "/home/felipe/venv/lib/python3.9/site-packages/airflow/models/taskinstance.py", line 1518, in _run_raw_task
    self._execute_task_with_callbacks(context, test_mode, session=session)
  File "/home/felipe/venv/lib/python3.9/site-packages/airflow/models/taskinstance.py", line 1681, in _execute_task_with_callbacks
    result = self._execute_task(context, task_orig)
  File "/home/felipe/venv/lib/python3.9/site-packages/airflow/models/taskinstance.py", line 1744, in _execute_task
    result = execute_callable(context=context, **execute_callable_kwargs)
  File "/home/felipe/venv/lib/python3.9/site-packages/airflow/operators/python.py", line 192, in execute
    return_value = self.execute_callable()
  File "/home/felipe/venv/lib/python3.9/site-packages/airflow/operators/python.py", line 209, in execute_callable
    return self.python_callable(*self.op_args, **self.op_kwargs)
  File "/home/felipe/airflow/dags/example_desafio.py", line 44, in extract_order
    con = sqlite3.connect("home/felipe/airflow_tooltorial/data/Northwind_small.sqlite")
sqlite3.OperationalError: unable to open database file

During handling of the above exception, another exception occurred:

Traceback (most recent call last):
  File "/home/felipe/venv/lib/python3.9/site-packages/airflow/models/taskinstance.py", line 2420, in email_alert
    send_email(task.email, subject, html_content)
  File "/home/felipe/venv/lib/python3.9/site-packages/airflow/utils/email.py", line 80, in send_email
    return backend(
  File "/home/felipe/venv/lib/python3.9/site-packages/airflow/utils/email.py", line 154, in send_email_smtp
    send_mime_email(e_from=mail_from, e_to=recipients, mime_msg=msg, conn_id=conn_id, dryrun=dryrun)
  File "/home/felipe/venv/lib/python3.9/site-packages/airflow/utils/email.py", line 272, in send_mime_email
    smtp_conn = _get_smtp_connection(smtp_host, smtp_port, smtp_timeout, smtp_ssl)
  File "/home/felipe/venv/lib/python3.9/site-packages/airflow/utils/email.py", line 316, in _get_smtp_connection
    return smtplib.SMTP(host=host, port=port, timeout=timeout)
  File "/usr/lib/python3.9/smtplib.py", line 255, in __init__
    (code, msg) = self.connect(host, port)
  File "/usr/lib/python3.9/smtplib.py", line 341, in connect
    self.sock = self._get_socket(host, port, self.timeout)
  File "/usr/lib/python3.9/smtplib.py", line 312, in _get_socket
    return socket.create_connection((host, port), timeout,
  File "/usr/lib/python3.9/socket.py", line 844, in create_connection
    raise err
  File "/usr/lib/python3.9/socket.py", line 832, in create_connection
    sock.connect(sa)
ConnectionRefusedError: [Errno 111] Connection refused

During handling of the above exception, another exception occurred:

Traceback (most recent call last):
  File "/home/felipe/venv/lib/python3.9/site-packages/airflow/models/taskinstance.py", line 2005, in handle_failure
    self.email_alert(error, task)
  File "/home/felipe/venv/lib/python3.9/site-packages/airflow/models/taskinstance.py", line 2422, in email_alert
    send_email(task.email, subject, html_content_err)
  File "/home/felipe/venv/lib/python3.9/site-packages/airflow/utils/email.py", line 80, in send_email
    return backend(
  File "/home/felipe/venv/lib/python3.9/site-packages/airflow/utils/email.py", line 154, in send_email_smtp
    send_mime_email(e_from=mail_from, e_to=recipients, mime_msg=msg, conn_id=conn_id, dryrun=dryrun)
  File "/home/felipe/venv/lib/python3.9/site-packages/airflow/utils/email.py", line 272, in send_mime_email
    smtp_conn = _get_smtp_connection(smtp_host, smtp_port, smtp_timeout, smtp_ssl)
  File "/home/felipe/venv/lib/python3.9/site-packages/airflow/utils/email.py", line 316, in _get_smtp_connection
    return smtplib.SMTP(host=host, port=port, timeout=timeout)
  File "/usr/lib/python3.9/smtplib.py", line 255, in __init__
    (code, msg) = self.connect(host, port)
  File "/usr/lib/python3.9/smtplib.py", line 341, in connect
    self.sock = self._get_socket(host, port, self.timeout)
  File "/usr/lib/python3.9/smtplib.py", line 312, in _get_socket
    return socket.create_connection((host, port), timeout,
  File "/usr/lib/python3.9/socket.py", line 844, in create_connection
    raise err
  File "/usr/lib/python3.9/socket.py", line 832, in create_connection
    sock.connect(sa)
ConnectionRefusedError: [Errno 111] Connection refused
[2023-11-03T01:37:43.046-0300] {standard_task_runner.py:104} ERROR - Failed to execute job 4 for task extract_order_csv (unable to open database file; 19432)
[2023-11-03T01:37:43.067-0300] {local_task_job_runner.py:228} INFO - Task exited with return code 1
[2023-11-03T01:37:43.076-0300] {taskinstance.py:2778} INFO - 0 downstream tasks scheduled from follow-on schedule check
